Workbook
Name Score: 'Risk Assessment'!$R$7:$S$18

Sheet Risk Assessment
E1: RISK ASSESSMENT
C3: Location: | F3: Date of Assessment:
C4: Position: | F4: Assessed by:
C5: Contractors available: | F5: Approval:
C7: Area | D7: Critical Activity or Equipment | E7: Hazard/Risk | F7: Consequence | G7: Likelihood | H7: Risk | I7: Safeguards needed (or in place) to reduce risk to acceptable level | J7: Consequence | K7: Likelihood | L7: Residual Risk after Safeguards | M7: Accept Risk (Y/N)
B8: 1 | C8: Health, Safety, Security, and Environment | F8: 4-Major | G8: 4-Possible | H8: =IF(OR(F8="",G8=""),"",INDEX(Matrix!$C$5:$H$10,MATCH('Risk Assessment'!G8,Matrix!$C$5:$C$10,0),MATCH('Risk Assessment'!F8,Matrix!$C$5:$H$5,0))) -> High | J8: 2-Minor | K8: 5-Rare | L8: =IF(OR(J8="",K8=""),"",INDEX(Matrix!$C$5:$H$10,MATCH('Risk Assessment'!K8,Matrix!$C$5:$C$10,0),MATCH('Risk Assessment'!J8,Matrix!$C$5:$H$5,0))) -> Low | M8: No
B9: 2 | H9: =IF(OR(F9="",G9=""),"",INDEX(Matrix!$C$5:$H$10,MATCH('Risk Assessment'!G9,Matrix!$C$5:$C$10,0),MATCH('Risk Assessment'!F9,Matrix!$C$5:$H$5,0))) | L9: =IF(OR(J9="",K9=""),"",INDEX(Matrix!$C$5:$H$10,MATCH('Risk Assessment'!K9,Matrix!$C$5:$C$10,0),MATCH('Risk Assessment'!J9,Matrix!$C$5:$H$5,0)))
B10: 3 | H10: =IF(OR(F10="",G10=""),"",INDEX(Matrix!$C$5:$H$10,MATCH('Risk Assessment'!G10,Matrix!$C$5:$C$10,0),MATCH('Risk Assessment'!F10,Matrix!$C$5:$H$5,0))) | L10: =IF(OR(J10="",K10=""),"",INDEX(Matrix!$C$5:$H$10,MATCH('Risk Assessment'!K10,Matrix!$C$5:$C$10,0),MATCH('Risk Assessment'!J10,Matrix!$C$5:$H$5,0)))
B11: 4 | H11: =IF(OR(F11="",G11=""),"",INDEX(Matrix!$C$5:$H$10,MATCH('Risk Assessment'!G11,Matrix!$C$5:$C$10,0),MATCH('Risk Assessment'!F11,Matrix!$C$5:$H$5,0))) | L11: =IF(OR(J11="",K11=""),"",INDEX(Matrix!$C$5:$H$10,MATCH('Risk Assessment'!K11,Matrix!$C$5:$C$10,0),MATCH('Risk Assessment'!J11,Matrix!$C$5:$H$5,0)))
B12: 5 | H12: =IF(OR(F12="",G12=""),"",INDEX(Matrix!$C$5:$H$10,MATCH('Risk Assessment'!G12,Matrix!$C$5:$C$10,0),MATCH('Risk Assessment'!F12,Matrix!$C$5:$H$5,0))) | L12: =IF(OR(J12="",K12=""),"",INDEX(Matrix!$C$5:$H$10,MATCH('Risk Assessment'!K12,Matrix!$C$5:$C$10,0),MATCH('Risk Assessment'!J12,Matrix!$C$5:$H$5,0)))
B13: 6 | H13: =IF(OR(F13="",G13=""),"",INDEX(Matrix!$C$5:$H$10,MATCH('Risk Assessment'!G13,Matrix!$C$5:$C$10,0),MATCH('Risk Assessment'!F13,Matrix!$C$5:$H$5,0))) | L13: =IF(OR(J13="",K13=""),"",INDEX(Matrix!$C$5:$H$10,MATCH('Risk Assessment'!K13,Matrix!$C$5:$C$10,0),MATCH('Risk Assessment'!J13,Matrix!$C$5:$H$5,0)))
B14: 7 | H14: =IF(OR(F14="",G14=""),"",INDEX(Matrix!$C$5:$H$10,MATCH('Risk Assessment'!G14,Matrix!$C$5:$C$10,0),MATCH('Risk Assessment'!F14,Matrix!$C$5:$H$5,0))) | L14: =IF(OR(J14="",K14=""),"",INDEX(Matrix!$C$5:$H$10,MATCH('Risk Assessment'!K14,Matrix!$C$5:$C$10,0),MATCH('Risk Assessment'!J14,Matrix!$C$5:$H$5,0)))
B15: 8 | H15: =IF(OR(F15="",G15=""),"",INDEX(Matrix!$C$5:$H$10,MATCH('Risk Assessment'!G15,Matrix!$C$5:$C$10,0),MATCH('Risk Assessment'!F15,Matrix!$C$5:$H$5,0))) | L15: =IF(OR(J15="",K15=""),"",INDEX(Matrix!$C$5:$H$10,MATCH('Risk Assessment'!K15,Matrix!$C$5:$C$10,0),MATCH('Risk Assessment'!J15,Matrix!$C$5:$H$5,0)))
B16: 9 | H16: =IF(OR(F16="",G16=""),"",INDEX(Matrix!$C$5:$H$10,MATCH('Risk Assessment'!G16,Matrix!$C$5:$C$10,0),MATCH('Risk Assessment'!F16,Matrix!$C$5:$H$5,0))) | L16: =IF(OR(J16="",K16=""),"",INDEX(Matrix!$C$5:$H$10,MATCH('Risk Assessment'!K16,Matrix!$C$5:$C$10,0),MATCH('Risk Assessment'!J16,Matrix!$C$5:$H$5,0)))
B17: 10 | C17: Environmental Conditions | H17: =IF(OR(F17="",G17=""),"",INDEX(Matrix!$C$5:$H$10,MATCH('Risk Assessment'!G17,Matrix!$C$5:$C$10,0),MATCH('Risk Assessment'!F17,Matrix!$C$5:$H$5,0))) | L17: =IF(OR(J17="",K17=""),"",INDEX(Matrix!$C$5:$H$10,MATCH('Risk Assessment'!K17,Matrix!$C$5:$C$10,0),MATCH('Risk Assessment'!J17,Matrix!$C$5:$H$5,0)))
B18: 11 | H18: =IF(OR(F18="",G18=""),"",INDEX(Matrix!$C$5:$H$10,MATCH('Risk Assessment'!G18,Matrix!$C$5:$C$10,0),MATCH('Risk Assessment'!F18,Matrix!$C$5:$H$5,0))) | L18: =IF(OR(J18="",K18=""),"",INDEX(Matrix!$C$5:$H$10,MATCH('Risk Assessment'!K18,Matrix!$C$5:$C$10,0),MATCH('Risk Assessment'!J18,Matrix!$C$5:$H$5,0)))
B19: 12 | H19: =IF(OR(F19="",G19=""),"",INDEX(Matrix!$C$5:$H$10,MATCH('Risk Assessment'!G19,Matrix!$C$5:$C$10,0),MATCH('Risk Assessment'!F19,Matrix!$C$5:$H$5,0))) | L19: =IF(OR(J19="",K19=""),"",INDEX(Matrix!$C$5:$H$10,MATCH('Risk Assessment'!K19,Matrix!$C$5:$C$10,0),MATCH('Risk Assessment'!J19,Matrix!$C$5:$H$5,0)))
B20: 13 | H20: =IF(OR(F20="",G20=""),"",INDEX(Matrix!$C$5:$H$10,MATCH('Risk Assessment'!G20,Matrix!$C$5:$C$10,0),MATCH('Risk Assessment'!F20,Matrix!$C$5:$H$5,0))) | L20: =IF(OR(J20="",K20=""),"",INDEX(Matrix!$C$5:$H$10,MATCH('Risk Assessment'!K20,Matrix!$C$5:$C$10,0),MATCH('Risk Assessment'!J20,Matrix!$C$5:$H$5,0)))
B21: 14 | H21: =IF(OR(F21="",G21=""),"",INDEX(Matrix!$C$5:$H$10,MATCH('Risk Assessment'!G21,Matrix!$C$5:$C$10,0),MATCH('Risk Assessment'!F21,Matrix!$C$5:$H$5,0))) | L21: =IF(OR(J21="",K21=""),"",INDEX(Matrix!$C$5:$H$10,MATCH('Risk Assessment'!K21,Matrix!$C$5:$C$10,0),MATCH('Risk Assessment'!J21,Matrix!$C$5:$H$5,0)))
B22: 15 | H22: =IF(OR(F22="",G22=""),"",INDEX(Matrix!$C$5:$H$10,MATCH('Risk Assessment'!G22,Matrix!$C$5:$C$10,0),MATCH('Risk Assessment'!F22,Matrix!$C$5:$H$5,0))) | L22: =IF(OR(J22="",K22=""),"",INDEX(Matrix!$C$5:$H$10,MATCH('Risk Assessment'!K22,Matrix!$C$5:$C$10,0),MATCH('Risk Assessment'!J22,Matrix!$C$5:$H$5,0)))
B23: 16 | H23: =IF(OR(F23="",G23=""),"",INDEX(Matrix!$C$5:$H$10,MATCH('Risk Assessment'!G23,Matrix!$C$5:$C$10,0),MATCH('Risk Assessment'!F23,Matrix!$C$5:$H$5,0))) | L23: =IF(OR(J23="",K23=""),"",INDEX(Matrix!$C$5:$H$10,MATCH('Risk Assessment'!K23,Matrix!$C$5:$C$10,0),MATCH('Risk Assessment'!J23,Matrix!$C$5:$H$5,0)))
B24: 17 | H24: =IF(OR(F24="",G24=""),"",INDEX(Matrix!$C$5:$H$10,MATCH('Risk Assessment'!G24,Matrix!$C$5:$C$10,0),MATCH('Risk Assessment'!F24,Matrix!$C$5:$H$5,0))) | L24: =IF(OR(J24="",K24=""),"",INDEX(Matrix!$C$5:$H$10,MATCH('Risk Assessment'!K24,Matrix!$C$5:$C$10,0),MATCH('Risk Assessment'!J24,Matrix!$C$5:$H$5,0)))
B25: 18 | C25: Cargo Operations | H25: =IF(OR(F25="",G25=""),"",INDEX(Matrix!$C$5:$H$10,MATCH('Risk Assessment'!G25,Matrix!$C$5:$C$10,0),MATCH('Risk Assessment'!F25,Matrix!$C$5:$H$5,0))) | L25: =IF(OR(J25="",K25=""),"",INDEX(Matrix!$C$5:$H$10,MATCH('Risk Assessment'!K25,Matrix!$C$5:$C$10,0),MATCH('Risk Assessment'!J25,Matrix!$C$5:$H$5,0)))
B26: 19 | H26: =IF(OR(F26="",G26=""),"",INDEX(Matrix!$C$5:$H$10,MATCH('Risk Assessment'!G26,Matrix!$C$5:$C$10,0),MATCH('Risk Assessment'!F26,Matrix!$C$5:$H$5,0))) | L26: =IF(OR(J26="",K26=""),"",INDEX(Matrix!$C$5:$H$10,MATCH('Risk Assessment'!K26,Matrix!$C$5:$C$10,0),MATCH('Risk Assessment'!J26,Matrix!$C$5:$H$5,0)))
B27: 20 | H27: =IF(OR(F27="",G27=""),"",INDEX(Matrix!$C$5:$H$10,MATCH('Risk Assessment'!G27,Matrix!$C$5:$C$10,0),MATCH('Risk Assessment'!F27,Matrix!$C$5:$H$5,0))) | L27: =IF(OR(J27="",K27=""),"",INDEX(Matrix!$C$5:$H$10,MATCH('Risk Assessment'!K27,Matrix!$C$5:$C$10,0),MATCH('Risk Assessment'!J27,Matrix!$C$5:$H$5,0)))
B28: 21 | H28: =IF(OR(F28="",G28=""),"",INDEX(Matrix!$C$5:$H$10,MATCH('Risk Assessment'!G28,Matrix!$C$5:$C$10,0),MATCH('Risk Assessment'!F28,Matrix!$C$5:$H$5,0))) | L28: =IF(OR(J28="",K28=""),"",INDEX(Matrix!$C$5:$H$10,MATCH('Risk Assessment'!K28,Matrix!$C$5:$C$10,0),MATCH('Risk Assessment'!J28,Matrix!$C$5:$H$5,0)))
B29: 22 | C29: STS Operations and Equipment | H29: =IF(OR(F29="",G29=""),"",INDEX(Matrix!$C$5:$H$10,MATCH('Risk Assessment'!G29,Matrix!$C$5:$C$10,0),MATCH('Risk Assessment'!F29,Matrix!$C$5:$H$5,0))) | L29: =IF(OR(J29="",K29=""),"",INDEX(Matrix!$C$5:$H$10,MATCH('Risk Assessment'!K29,Matrix!$C$5:$C$10,0),MATCH('Risk Assessment'!J29,Matrix!$C$5:$H$5,0)))
B30: 23 | H30: =IF(OR(F30="",G30=""),"",INDEX(Matrix!$C$5:$H$10,MATCH('Risk Assessment'!G30,Matrix!$C$5:$C$10,0),MATCH('Risk Assessment'!F30,Matrix!$C$5:$H$5,0))) | L30: =IF(OR(J30="",K30=""),"",INDEX(Matrix!$C$5:$H$10,MATCH('Risk Assessment'!K30,Matrix!$C$5:$C$10,0),MATCH('Risk Assessment'!J30,Matrix!$C$5:$H$5,0)))
B31: 24 | H31: =IF(OR(F31="",G31=""),"",INDEX(Matrix!$C$5:$H$10,MATCH('Risk Assessment'!G31,Matrix!$C$5:$C$10,0),MATCH('Risk Assessment'!F31,Matrix!$C$5:$H$5,0))) | L31: =IF(OR(J31="",K31=""),"",INDEX(Matrix!$C$5:$H$10,MATCH('Risk Assessment'!K31,Matrix!$C$5:$C$10,0),MATCH('Risk Assessment'!J31,Matrix!$C$5:$H$5,0)))
B32: 25 | H32: =IF(OR(F32="",G32=""),"",INDEX(Matrix!$C$5:$H$10,MATCH('Risk Assessment'!G32,Matrix!$C$5:$C$10,0),MATCH('Risk Assessment'!F32,Matrix!$C$5:$H$5,0))) | L32: =IF(OR(J32="",K32=""),"",INDEX(Matrix!$C$5:$H$10,MATCH('Risk Assessment'!K32,Matrix!$C$5:$C$10,0),MATCH('Risk Assessment'!J32,Matrix!$C$5:$H$5,0)))
B33: 26 | H33: =IF(OR(F33="",G33=""),"",INDEX(Matrix!$C$5:$H$10,MATCH('Risk Assessment'!G33,Matrix!$C$5:$C$10,0),MATCH('Risk Assessment'!F33,Matrix!$C$5:$H$5,0))) | L33: =IF(OR(J33="",K33=""),"",INDEX(Matrix!$C$5:$H$10,MATCH('Risk Assessment'!K33,Matrix!$C$5:$C$10,0),MATCH('Risk Assessment'!J33,Matrix!$C$5:$H$5,0)))
B34: 27 | H34: =IF(OR(F34="",G34=""),"",INDEX(Matrix!$C$5:$H$10,MATCH('Risk Assessment'!G34,Matrix!$C$5:$C$10,0),MATCH('Risk Assessment'!F34,Matrix!$C$5:$H$5,0))) | L34: =IF(OR(J34="",K34=""),"",INDEX(Matrix!$C$5:$H$10,MATCH('Risk Assessment'!K34,Matrix!$C$5:$C$10,0),MATCH('Risk Assessment'!J34,Matrix!$C$5:$H$5,0)))
B35: 28 | H35: =IF(OR(F35="",G35=""),"",INDEX(Matrix!$C$5:$H$10,MATCH('Risk Assessment'!G35,Matrix!$C$5:$C$10,0),MATCH('Risk Assessment'!F35,Matrix!$C$5:$H$5,0))) | L35: =IF(OR(J35="",K35=""),"",INDEX(Matrix!$C$5:$H$10,MATCH('Risk Assessment'!K35,Matrix!$C$5:$C$10,0),MATCH('Risk Assessment'!J35,Matrix!$C$5:$H$5,0)))
B36: 29 | H36: =IF(OR(F36="",G36=""),"",INDEX(Matrix!$C$5:$H$10,MATCH('Risk Assessment'!G36,Matrix!$C$5:$C$10,0),MATCH('Risk Assessment'!F36,Matrix!$C$5:$H$5,0))) | L36: =IF(OR(J36="",K36=""),"",INDEX(Matrix!$C$5:$H$10,MATCH('Risk Assessment'!K36,Matrix!$C$5:$C$10,0),MATCH('Risk Assessment'!J36,Matrix!$C$5:$H$5,0)))
B37: 30 | C37: Communications | H37: =IF(OR(F37="",G37=""),"",INDEX(Matrix!$C$5:$H$10,MATCH('Risk Assessment'!G37,Matrix!$C$5:$C$10,0),MATCH('Risk Assessment'!F37,Matrix!$C$5:$H$5,0))) | L37: =IF(OR(J37="",K37=""),"",INDEX(Matrix!$C$5:$H$10,MATCH('Risk Assessment'!K37,Matrix!$C$5:$C$10,0),MATCH('Risk Assessment'!J37,Matrix!$C$5:$H$5,0)))
B38: 31 | H38: =IF(OR(F38="",G38=""),"",INDEX(Matrix!$C$5:$H$10,MATCH('Risk Assessment'!G38,Matrix!$C$5:$C$10,0),MATCH('Risk Assessment'!F38,Matrix!$C$5:$H$5,0))) | L38: =IF(OR(J38="",K38=""),"",INDEX(Matrix!$C$5:$H$10,MATCH('Risk Assessment'!K38,Matrix!$C$5:$C$10,0),MATCH('Risk Assessment'!J38,Matrix!$C$5:$H$5,0)))
B39: 32 | H39: =IF(OR(F39="",G39=""),"",INDEX(Matrix!$C$5:$H$10,MATCH('Risk Assessment'!G39,Matrix!$C$5:$C$10,0),MATCH('Risk Assessment'!F39,Matrix!$C$5:$H$5,0))) | L39: =IF(OR(J39="",K39=""),"",INDEX(Matrix!$C$5:$H$10,MATCH('Risk Assessment'!K39,Matrix!$C$5:$C$10,0),MATCH('Risk Assessment'!J39,Matrix!$C$5:$H$5,0)))
B40: 33 | C40: Location | H40: =IF(OR(F40="",G40=""),"",INDEX(Matrix!$C$5:$H$10,MATCH('Risk Assessment'!G40,Matrix!$C$5:$C$10,0),MATCH('Risk Assessment'!F40,Matrix!$C$5:$H$5,0))) | L40: =IF(OR(J40="",K40=""),"",INDEX(Matrix!$C$5:$H$10,MATCH('Risk Assessment'!K40,Matrix!$C$5:$C$10,0),MATCH('Risk Assessment'!J40,Matrix!$C$5:$H$5,0)))
B41: 34 | H41: =IF(OR(F41="",G41=""),"",INDEX(Matrix!$C$5:$H$10,MATCH('Risk Assessment'!G41,Matrix!$C$5:$C$10,0),MATCH('Risk Assessment'!F41,Matrix!$C$5:$H$5,0))) | L41: =IF(OR(J41="",K41=""),"",INDEX(Matrix!$C$5:$H$10,MATCH('Risk Assessment'!K41,Matrix!$C$5:$C$10,0),MATCH('Risk Assessment'!J41,Matrix!$C$5:$H$5,0)))
B42: 35 | H42: =IF(OR(F42="",G42=""),"",INDEX(Matrix!$C$5:$H$10,MATCH('Risk Assessment'!G42,Matrix!$C$5:$C$10,0),MATCH('Risk Assessment'!F42,Matrix!$C$5:$H$5,0))) | L42: =IF(OR(J42="",K42=""),"",INDEX(Matrix!$C$5:$H$10,MATCH('Risk Assessment'!K42,Matrix!$C$5:$C$10,0),MATCH('Risk Assessment'!J42,Matrix!$C$5:$H$5,0)))
...

Sheet Matrix
C5: Consequence / Likelihood | D5: 1-Insignificant | E5: 2-Minor | F5: 3-Moderate | G5: 4-Major | H5: 5-Catastrophic
C6: 1-Frequent | D6: Moderate | E6: High | F6: Extreme | G6: Extreme | H6: Extreme
C7: 2-Often | D7: Moderate | E7: High | F7: High | G7: Extreme | H7: Extreme
C8: 3-Likely | D8: Low | E8: Moderate | F8: High | G8: High | H8: Extreme
C9: 4-Possible | D9: Low | E9: Moderate | F9: Moderate | G9: High | H9: High
C10: 5-Rare | D10: Low | E10: Low | F10: Low Risk | G10: Moderate | H10: Moderate
